<?xml version='1.0'?>
<sdf version='1.9'>

  <model name='centaur_sim_scene'>
  <link name='ground'>
    <visual name='visual'>
      <pose>0 0 -0.025 0 0 0</pose>
      <geometry>
        <box>  <size>25.0 10.0 0.05</size> </box>
      </geometry>
      <material>
        <diffuse>0.9 0.8 0.7 0.6</diffuse>
      </material>
    </visual> 
    <collision name="collision">
      <pose>0 0 -0.025 0 0 0</pose>
      <geometry>
        <box>  <size>25.0 10.0 0.05</size> </box>
      </geometry>
    </collision>
  </link>

  <frame name='x_block_init_frame' attached_to='ground'> 
    <pose relative_to='ground'>0.217 0 0.990 0 0 0</pose>
  </frame>
  <link name='x_block'>
    <pose relative_to='x_block_init_frame'>0 0 0 0 0 0</pose>
    <!-- <visual name='visual'>
      <pose relative_to='x_block_init_frame'>0 0 0 0 0 0</pose>
      <geometry> <box> <size>0.02 0.02 0.02</size> </box> </geometry>
      <material>
        <diffuse>0.5 0.0 0.0 0.6</diffuse>
      </material>
    </visual>   -->
  </link>
  <joint name='x_prismastic_joint' type='prismatic'>
    <pose relative_to='x_block_init_frame'>0 0 0 0 0 0</pose>
    <parent>ground</parent>
    <child>x_block</child>
    <axis>  
      <xyz>1 0 0</xyz>
      <limit> 
        <!-- <lower>-0.8028514559173915</lower>
        <upper>0.8028514559173915</upper> -->
        <!-- <effort>1000000.0</effort> -->
        <!-- <velocity>1000.0</velocity> -->
      </limit>
    </axis>
  </joint> 

  <frame name='y_block_init_frame' attached_to='x_block'> 
    <pose relative_to='x_block'>0.0 0 0 0 0 0</pose>
  </frame>
  <link name='y_block'>
    <pose relative_to='y_block_init_frame'>0 0 0 0 0 0</pose>
    <!-- <visual name='visual'>
      <pose relative_to='y_block_init_frame'>0 0 0 0 0 0</pose>
      <geometry> <box> <size>0.02 0.02 0.02</size> </box> </geometry>
      <material>
        <diffuse>0.0 0.5 0.0 0.6</diffuse>
      </material>
    </visual>   -->
  </link>
  <joint name='y_prismastic_joint' type='prismatic'>
    <pose relative_to='y_block_init_frame'>0 0 0 0 0 0</pose>
    <parent>x_block</parent>
    <child>y_block</child>
    <axis>  
      <xyz>0 1 0</xyz>
      <limit> 
        <!-- <lower>-0.8028514559173915</lower>
        <upper>0.8028514559173915</upper> -->
        <!-- <effort>1000000.0</effort>
        <velocity>1000.0</velocity> -->
      </limit>
    </axis>
  </joint>  

  <frame name='z_block_init_frame' attached_to='y_block'> 
    <pose relative_to='y_block'>0 0.0 0 0 0 0</pose>
  </frame>
  <link name='z_block'>
    <pose relative_to='z_block_init_frame'>0 0 0 0 0 0</pose>
    <visual name='visual'>
      <pose relative_to='z_block_init_frame'>0.02 0 0.1 0 0 0</pose>
      <geometry> <box> <size>0.02 0.3 0.4</size> </box> </geometry>
      <material>
        <diffuse>0.1 0.1 0.4 0.2</diffuse>
      </material>
    </visual>  
  </link>
  <joint name='z_prismastic_joint' type='prismatic'>
    <pose relative_to='z_block_init_frame'>0 0 0 0 0 0</pose>
    <parent>y_block</parent>
    <child>z_block</child>
    <axis>  
      <xyz>0 0 1</xyz>
      <limit> 
        <!-- <lower>-0.8028514559173915</lower>
        <upper>0.8028514559173915</upper> -->
        <!-- <effort>1000000.0</effort>
        <velocity>1000.0</velocity> -->
      </limit>
    </axis>
  </joint>  

  <frame name='f_t_sensor_frame' attached_to='z_block'> 
    <pose relative_to='z_block'>0 0 -0.0 0 0 0</pose>
  </frame>
  <link name='f_t_sensor_link'>
    <pose relative_to='f_t_sensor_frame'>0 0 0 0 0 0</pose>
    <visual name='visual'>
      <pose relative_to='f_t_sensor_frame'>0 0 0 0 0 0</pose>
      <geometry>
       <box> <size>0.1 0.1 0.1</size> </box> 
      </geometry>
      <material>
        <diffuse>1.0 0.423529411765 0.0392156862745 0.5</diffuse>
      </material>
    </visual>  
  </link>
  <joint name='f_t_sensor_fixed_joint' type='fixed'>
    <pose relative_to='f_t_sensor_frame'>0.0000 0 0 0 0 0</pose>
    <parent>z_block</parent>
    <child>f_t_sensor_link</child>
  </joint>



  <frame name='ball_joint_frame' attached_to='f_t_sensor_link'> 
    <pose relative_to='f_t_sensor_link'>-0.001 0 0 0 0 0</pose>
  </frame>

  <joint name='ball_joint' type='ball'>
    <pose relative_to='ball_joint_frame'>0 0 0 0 0 0</pose>
    <parent>f_t_sensor_link</parent>
    <child>floating_base</child>
    <!-- <axis>
    <dynamics>
      <damping> 1000.0 </damping>
    </dynamics>
    </axis> -->
    
  </joint>

  <link name='floating_base'>
    <pose relative_to='ball_joint_frame'>-0.216 0 -0.09 0 0 0</pose>
    <!-- <visual name='visual'>
      <pose relative_to='ball_joint_frame'>-0.216 0 -0.09 0 0 0</pose>
      <geometry> <sphere> <radius>0.02</radius> </sphere> </geometry>
      <material>
        <diffuse>0.8 0.1 0.1 0.1</diffuse>
      </material>
    </visual>   -->
  </link>

  <joint name='floating_base_fixed_to_torso' type='fixed'>
    <parent>floating_base</parent>
    <child>torso</child>
  </joint>

  <link name='torso'>
    <pose relative_to='floating_base'>0 0 0 0 0 0</pose>
    <visual name='visual'>
      <pose relative_to='floating_base'>0 0 0 0 0 0</pose>
      <geometry> 
        <box> <size>0.432 0.2 0.22</size> </box>
      </geometry>
      <material>
        <diffuse>0.2 0.2 0.2 0.4</diffuse>
      </material>
    </visual>
    <inertial>
      <mass>20.0</mass>
      <inertia> <ixx>0.1473</ixx> <iyy>0.3917</iyy> <izz>0.3777</izz> </inertia>
    </inertial>
    <collision name='collision'>
      <pose relative_to='floating_base'>0 0 0 0 0 0</pose>
      <geometry> 
        <box> <size>0.432 0.2 0.22</size> </box>
      </geometry>
    </collision>
  </link>

  <frame name='left_abad_joint_frame' attached_to='torso'>
    <pose relative_to='torso'>-0.048 0.173 0 0 0 0</pose>
  </frame>

  <joint name='left_abad_joint' type='revolute'>
    <pose relative_to='left_abad_joint_frame'>0 0 0 0 0 0</pose>
    <parent>torso</parent>
    <child>left_hip_from_abad</child>
    <axis>  
      <xyz>1 0 0</xyz>
      <limit> 
        <lower>-0.8028514559173915</lower>
        <upper>0.8028514559173915</upper>
        <effort>140.0</effort>
        <velocity>93.0</velocity>
      </limit>
    </axis>
  </joint>

  <link name='left_hip_from_abad'>
    <pose relative_to='left_abad_joint_frame'>0 0 0 0 0 0</pose>
    <visual name='visual'>
      <pose relative_to='left_abad_joint_frame'>-0.14 0.04 0 1.5707963267948966 0 0</pose>
      <geometry>
        <cylinder> <length>0.127</length> <radius>0.084</radius> </cylinder>
      </geometry>
      <material>
        <diffuse>0.913725490196 0.913725490196 0.847058823529 0.6</diffuse>
      </material>
    </visual>
    <collision name='collision'>
      <pose relative_to='left_abad_joint_frame'>-0.14 0 0 1.5707963267948966 0 0</pose>
      <geometry>
        <cylinder> <length>0.127</length> <radius>0.084</radius> </cylinder>
      </geometry>
    </collision>
    <inertial>
      <pose>-0.14 0 0 1.5707963267948966 0 0</pose>
      <mass>1.7</mass>
      <inertia> <ixx>0.0053</ixx> <iyy>0.0053</iyy> <izz>0.006</izz> </inertia>
    </inertial>
  </link>

  <frame name='left_hip_joint_frame' attached_to='left_hip_from_abad'>
    <pose relative_to='left_hip_from_abad'>-0.14 0.04 0 0 0 0</pose>
  </frame>

  <joint name='left_hip_joint' type='revolute'>
    <pose relative_to='left_hip_joint_frame'>0 0 0 0 0 0</pose>
    <parent>left_hip_from_abad</parent>
    <child>left_thigh_from_hip</child>
    <axis>  
      <xyz>0 1 0</xyz>
      <limit> 
        <lower>-0.8028514559173915</lower>
        <upper>0.8028514559173915</upper>
        <effort>140.0</effort>
        <velocity>93.0</velocity>
      </limit>
    </axis>
  </joint>

  <link name='left_thigh_from_hip'>
    <pose relative_to='left_hip_joint_frame'>0 0 0 0 0 0</pose>
    <visual name='visual'>
      <pose relative_to='left_hip_joint_frame'>0 0 -0.256 0 0 0</pose>
      <geometry>
        <cylinder> <length>0.512</length> <radius>0.0175</radius> </cylinder>
      </geometry>
      <material>
        <diffuse>0.913725490196 0.913725490196 0.847058823529 0.6</diffuse>
      </material>
    </visual>
    <collision name='collision'>
      <pose relative_to='left_hip_joint_frame'>0 0 -0.256 0 0 0</pose>
      <geometry>
        <cylinder> <length>0.512</length> <radius>0.0175</radius> </cylinder>
      </geometry>
    </collision>
    <inertial>
      <pose>0 0 -0.256 0 0 0</pose>
      <mass>0.5</mass>
      <inertia> <ixx>0.0141</ixx> <iyy>0.0141</iyy> <izz>0.0001</izz> </inertia>
    </inertial>
  </link>

  <frame name='left_knee_joint_frame' attached_to='left_thigh_from_hip'>
    <pose relative_to='left_thigh_from_hip'>0 0 -0.512 0 0 0</pose>
  </frame>

  <joint name='left_knee_joint' type='revolute'>
    <pose relative_to='left_knee_joint_frame'>0 0 0 0 0 0</pose>
    <parent>left_thigh_from_hip</parent>
    <child>left_shank_from_knee</child>
    <axis>  
      <xyz>0 1 0</xyz>
      <limit> 
        <lower>-1.5</lower>
        <upper>0.0</upper>
        <effort>140.0</effort>
        <velocity>93.0</velocity>
      </limit>
    </axis>
  </joint>

  <link name='left_shank_from_knee'>
    <pose relative_to='left_knee_joint_frame'>0 0 0 0 0 0</pose>
    <visual name='visual'>
      <pose relative_to='left_knee_joint_frame'>0 0 -0.24 0 0 0</pose>
      <geometry>
        <cylinder> <length>0.48</length> <radius>0.015</radius> </cylinder>
      </geometry>
      <material>
        <diffuse>0.913725490196 0.913725490196 0.847058823529 0.6</diffuse>
      </material>
    </visual>
    <collision name='collision'>
      <pose relative_to='left_knee_joint_frame'>0 0 -0.24 0 0 0</pose>
      <geometry>
        <cylinder> <length>0.48</length> <radius>0.015</radius> </cylinder>
      </geometry>
    </collision>
    <inertial>
      <pose>0 0 -0.24 0 0 0</pose>
      <mass>0.5</mass>
      <inertia> <ixx>0.0083</ixx> <iyy>0.0083</iyy> <izz>0.0001</izz> </inertia>
    </inertial>
  </link>

  <frame name='left_foot_joint_frame' attached_to='left_shank_from_knee'>
    <pose relative_to='left_shank_from_knee'>0 0 -0.49 0 0 0</pose>
  </frame>

  <joint name='left_foot_fixed_joint' type='fixed'>
    <pose relative_to='left_foot_joint_frame'>0 0 0 0 0 0</pose>
    <parent>left_shank_from_knee</parent>
    <child>left_foot</child>
  </joint>

  <link name='left_foot'>
    <pose relative_to='left_foot_joint_frame'>0 0 0 0 0 0</pose>
    <visual name='visual'>
      <pose relative_to='left_foot_joint_frame'>0 0 0 0 0 0</pose>
      <geometry>
        <sphere> <radius>0.02</radius> </sphere>
      </geometry>
      <material>
        <diffuse>1.0 0.423529411765 0.0392156862745 0.5</diffuse>
      </material>
    </visual>
    <collision name='collision'>
      <pose relative_to='left_foot_joint_frame'>0 0 0 0 0 0</pose>
      <geometry>
        <sphere> <radius>0.02</radius> </sphere>
      </geometry>
    </collision>
  </link>


<!-- right side -->

  <frame name='right_abad_joint_frame' attached_to='torso'>
    <pose relative_to='torso'>-0.048 -0.173 0 0 0 0</pose>
  </frame>

  <joint name='right_abad_joint' type='revolute'>
    <pose relative_to='right_abad_joint_frame'>0 0 0 0 0 0</pose>
    <parent>torso</parent>
    <child>right_hip_from_abad</child>
    <axis>  
      <xyz>1 0 0</xyz>
      <limit> 
        <lower>-0.8028514559173915</lower>
        <upper>0.8028514559173915</upper>
        <effort>140.0</effort>
        <velocity>93.0</velocity>
      </limit>
    </axis>
  </joint>

  <link name='right_hip_from_abad'>
    <pose relative_to='right_abad_joint_frame'>0 0 0 0 0 0</pose>
    <visual name='visual'>
      <pose relative_to='right_abad_joint_frame'>-0.14 -0.04 0 1.5707963267948966 0 0</pose>
      <geometry>
        <!-- <mesh> <uri>/home/haoyun/Data/Code/drake/workspace/centaur_sim/centaur_description/meshes/dae/hip.dae</uri> </mesh> -->
        <cylinder> <length>0.127</length> <radius>0.084</radius> </cylinder>
      </geometry>
      <material>
        <diffuse>0.913725490196 0.913725490196 0.847058823529 0.6</diffuse>
      </material>
    </visual>
    <collision name='collision'>
      <pose relative_to='right_abad_joint_frame'>-0.14 0 0 1.5707963267948966 0 0</pose>
      <geometry>
        <cylinder> <length>0.127</length> <radius>0.084</radius> </cylinder>
      </geometry>
    </collision>
    <inertial>
      <pose>-0.14 0 0 1.5707963267948966 0 0</pose>
      <mass>1.7</mass>
      <inertia> <ixx>0.0053</ixx> <iyy>0.0053</iyy> <izz>0.006</izz> </inertia>
    </inertial>
  </link>

  <frame name='right_hip_joint_frame' attached_to='right_hip_from_abad'>
    <pose relative_to='right_hip_from_abad'>-0.14 -0.04 0 0 0 0</pose>
  </frame>

  <joint name='right_hip_joint' type='revolute'>
    <pose relative_to='right_hip_joint_frame'>0 0 0 0 0 0</pose>
    <parent>right_hip_from_abad</parent>
    <child>right_thigh_from_hip</child>
    <axis>  
      <xyz>0 1 0</xyz>
      <limit> 
        <lower>-0.8028514559173915</lower>
        <upper>0.8028514559173915</upper>
        <effort>140.0</effort>
        <velocity>93.0</velocity>
      </limit>
    </axis>
  </joint>

  <link name='right_thigh_from_hip'>
    <pose relative_to='right_hip_joint_frame'>0 0 0 0 0 0</pose>
    <visual name='visual'>
      <pose relative_to='right_hip_joint_frame'>0 0 -0.256 0 0 0</pose>
      <geometry>
        <cylinder> <length>0.512</length> <radius>0.0175</radius> </cylinder>
      </geometry>
      <material>
        <diffuse>0.913725490196 0.913725490196 0.847058823529 0.6</diffuse>
      </material>
    </visual>
    <collision name='collision'>
      <pose relative_to='right_hip_joint_frame'>0 0 -0.256 0 0 0</pose>
      <geometry>
        <cylinder> <length>0.512</length> <radius>0.0175</radius> </cylinder>
      </geometry>
    </collision>
    <inertial>
      <pose>0 0 -0.256 0 0 0</pose>
      <mass>0.5</mass>
      <inertia> <ixx>0.0141</ixx> <iyy>0.0141</iyy> <izz>0.0001</izz> </inertia>
    </inertial>
  </link>

  <frame name='right_knee_joint_frame' attached_to='right_thigh_from_hip'>
    <pose relative_to='right_thigh_from_hip'>0 0 -0.512 0 0 0</pose>
  </frame>

  <joint name='right_knee_joint' type='revolute'>
    <pose relative_to='right_knee_joint_frame'>0 0 0 0 0 0</pose>
    <parent>right_thigh_from_hip</parent>
    <child>right_shank_from_knee</child>
    <axis>  
      <xyz>0 1 0</xyz>
      <limit> 
        <lower>-1.5</lower>
        <upper>0.0</upper>
        <effort>140.0</effort>
        <velocity>93.0</velocity>
      </limit>
    </axis>
  </joint>

  <link name='right_shank_from_knee'>
    <pose relative_to='right_knee_joint_frame'>0 0 0 0 0 0</pose>
    <visual name='visual'>
      <pose relative_to='right_knee_joint_frame'>0 0 -0.24 0 0 0</pose>
      <geometry>
        <cylinder> <length>0.48</length> <radius>0.015</radius> </cylinder>
      </geometry>
      <material>
        <diffuse>0.913725490196 0.913725490196 0.847058823529 0.6</diffuse>
      </material>
    </visual>
    <collision name='collision'>
      <pose relative_to='right_knee_joint_frame'>0 0 -0.24 0 0 0</pose>
      <geometry>
        <cylinder> <length>0.48</length> <radius>0.015</radius> </cylinder>
      </geometry>
    </collision>
    <inertial>
      <pose>0 0 -0.24 0 0 0</pose>
      <mass>0.5</mass>
      <inertia> <ixx>0.0083</ixx> <iyy>0.0083</iyy> <izz>0.0001</izz> </inertia>
    </inertial>
  </link>

  <frame name='right_foot_joint_frame' attached_to='right_shank_from_knee'>
    <pose relative_to='right_shank_from_knee'>0 0 -0.49 0 0 0</pose>
  </frame>

  <joint name='right_foot_fixed_joint' type='fixed'>
    <pose relative_to='right_foot_joint_frame'>0 0 0 0 0 0</pose>
    <parent>right_shank_from_knee</parent>
    <child>right_foot</child>
  </joint>

  <link name='right_foot'>
    <pose relative_to='right_foot_joint_frame'>0 0 0 0 0 0</pose>
    <visual name='visual'>
      <pose relative_to='right_foot_joint_frame'>0 0 0 0 0 0</pose>
      <geometry>
        <sphere> <radius>0.02</radius> </sphere>
      </geometry>
      <material>
        <diffuse>1.0 0.423529411765 0.0392156862745 0.5</diffuse>
      </material>
    </visual>
    <collision name='collision'>
      <pose relative_to='right_foot_joint_frame'>0 0 0 0 0 0</pose>
      <geometry>
        <sphere> <radius>0.02</radius> </sphere>
      </geometry>
    </collision>
  </link>


  <!-- terrai -->
  <!-- <frame name='box1_frame' attached_to='ground'>
    <pose relative_to='ground'>1.05 -0.5 0.0 0 0 0</pose>
  </frame>
  
   <joint name='box1_fix' type='fixed'>
    <pose relative_to='box1_frame'>0 0 0 0 0 0</pose>
    <parent>ground</parent>
    <child>box1</child>
  </joint> 

  <link name='box1'>
    <pose relative_to='box1_frame'>0 0 0 0 0 1.57</pose>
    <visual name='visual'>
      <pose relative_to='box1_frame'>0 0 0 0 0 1.57</pose>
      <geometry>
        <box> <size>0.7 0.14 0.14</size> </box>
      </geometry>
      <material>
        <diffuse>1.0 0.423529411765 0.0392156862745 0.5</diffuse>
      </material>
    </visual>
    <collision name='collision'>
      <pose relative_to='box1_frame'>0 0 0 0 0 1.57</pose>
      <geometry>
        <box> <size>0.7 0.14 0.14</size> </box>
      </geometry>
    </collision>
  </link> 


  <joint name='box2_fix' type='fixed'>
    <pose relative_to='box1_frame'>0 0 0 0 0 0</pose>
    <parent>ground</parent>
    <child>box2</child>
  </joint>  

  <link name='box2'>
    <pose relative_to='box1_frame'>0.52 1.0 0 0 0 1.57</pose>
    <visual name='visual'>
      <pose relative_to='box1_frame'>0.52 1.0 0 0 0 1.57</pose>
      <geometry>
        <box> <size>0.7 0.14 0.14</size> </box>
      </geometry>
      <material>
        <diffuse>1.0 0.423529411765 0.0392156862745 0.5</diffuse>
      </material>
    </visual>
    <collision name='collision'>
      <pose relative_to='box1_frame'>0.52 1.0 0 0 0 1.57</pose>
      <geometry>
        <box> <size>0.7 0.14 0.14</size> </box>
      </geometry>
    </collision>
  </link> 

  <joint name='box3_fix' type='fixed'>
    <pose relative_to='box1_frame'>0 0 0 0 0 0</pose>
    <parent>ground</parent>
    <child>box3</child>
  </joint>  

  <link name='box3'>
    <pose relative_to='box1_frame'>0.9 .0 0 0 0 1.57</pose>
    <visual name='visual'>
      <pose relative_to='box1_frame'>0.9 .0 0 0 0 1.57</pose>
      <geometry>
        <box> <size>0.7 0.14 0.14</size> </box>
      </geometry>
      <material>
        <diffuse>1.0 0.423529411765 0.0392156862745 0.5</diffuse>
      </material>
    </visual>
    <collision name='collision'>
      <pose relative_to='box1_frame'>0.9 0.0 0 0 0 1.57</pose>
      <geometry>
        <box> <size>0.7 0.14 0.14</size> </box>
      </geometry>
    </collision>
  </link> 
  

  <joint name='box4_fix' type='fixed'>
    <pose relative_to='box1_frame'>0 0 0 0 0 0</pose>
    <parent>ground</parent>
    <child>box4</child>
  </joint>  

  <link name='box4'>
    <pose relative_to='box1_frame'>1.7 1.0 0 0 0 1.57</pose>
    <visual name='visual'>
      <pose relative_to='box1_frame'>1.7 1.0 0 0 0 1.57</pose>
      <geometry>
        <box> <size>0.7 0.14 0.14</size> </box>
      </geometry>
      <material>
        <diffuse>1.0 0.423529411765 0.0392156862745 0.5</diffuse>
      </material>
    </visual>
    <collision name='collision'>
      <pose relative_to='box1_frame'>1.7 1.0 0 0 0 1.57</pose>
      <geometry>
        <box> <size>0.7 0.14 0.14</size> </box>
      </geometry>
    </collision>
  </link> 

  <joint name='box5_fix' type='fixed'>
    <pose relative_to='ground'>0 0 0 0 0 0</pose>
    <parent>ground</parent>
    <child>box5</child>
  </joint>  

  <link name='box5'>
    <pose relative_to='ground'>3.2 .0 0 0 0 1.57</pose>
    <visual name='visual'>
      <pose relative_to='ground'>3.2 .0 0 0 0 1.57</pose>
      <geometry>
        <box> <size>0.7 0.14 0.14</size> </box>
      </geometry>
      <material>
        <diffuse>1.0 0.423529411765 0.0392156862745 0.5</diffuse>
      </material>
    </visual>
    <collision name='collision'>
      <pose relative_to='ground'>3.2 .0 0 0 0 1.57</pose>
      <geometry>
        <box> <size>0.7 0.14 0.14</size> </box>
      </geometry>
    </collision>
  </link>  -->

  <!-- <joint name='load_frame' type='fixed'>
    <parent>floating_base</parent>
    <child>load_link</child>
  </joint>

  <link name='load_link'>
    <pose relative_to='floating_base'>0 0 0.11 0 0 0</pose>
    <visual name='visual'>
      <pose relative_to='floating_base'>0 0 0.11 0 0 0</pose>
      <geometry> 
        <box> <size>0.2 0.1 0.1</size> </box>
      </geometry>
      <material>
        <diffuse>0.8 0.1 0.1</diffuse>
      </material>
    </visual>
    <inertial>
      <mass>15.0</mass>
      <inertia> <ixx>0.01</ixx> <iyy>0.01</iyy> <izz>0.01</izz> </inertia>
    </inertial>
    <collision name='collision'>
      <pose relative_to='floating_base'>0 0 0 0 0 0</pose>
      <geometry> 
        <box> <size>0.2 0.2 0.1</size> </box>
      </geometry>
    </collision>
  </link> -->


  </model> 


</sdf>