<?xml version="1.0"?>
<robot name="centaur">

  <material name="black">
    <color rgba="0.0 0.0 0.0 0.8"/>
  </material>
  <material name="blue">
    <color rgba="0.0 0.0 0.8 0.8"/>
  </material>
  <material name="green">
    <color rgba="0.0 0.8 0.0 0.2"/>
  </material>
  <material name="grey">
    <color rgba="0.2 0.2 0.2 0.4"/>
  </material>
  <material name="silver">
    <color rgba="0.913725490196 0.913725490196 0.847058823529 0.6"/>
  </material>
  <material name="orange">
    <color rgba="1.0 0.423529411765 0.0392156862745 0.5"/>
  </material>
  <material name="brown">
    <color rgba="0.870588235294 0.811764705882 0.764705882353 0.7"/>
  </material>
  <material name="red">
    <color rgba="0.8 0.0 0.0 1.0"/>
  </material>
  <material name="white">
    <color rgba="1.0 1.0 1.0 1.0"/>
  </material>

  <link name="world">
    <visual name="visual">
      <origin rpy="0 0 0" xyz="0 0 -0.025"/>
      <geometry>
        <box size="12.0 10.0 0.05"/>
      </geometry>
      <material name="brown"/>
    </visual>
    <collision name="collision">
      <origin rpy="0 0 0" xyz="0 0 -0.025"/>
        <geometry>
        <box size="12.0 10.0 0.05"/>
      </geometry>
    </collision>
  </link>

  <joint name="world_to_base" type="fixed">
    <origin rpy="0 0 0" xyz="0 0 0.905"/>
    <parent link="world"/>
    <child link="floating_base"/>
  </joint>

  <link name="floating_base">
    <visual>
      <origin rpy="0 0 0" xyz="0 0 0"/>
        <geometry>
          <box size="0.001 0.001 0.001"/>
        </geometry>
    </visual>    
  </link>

  <joint name="floating_base_to_torso" type="fixed">
    <origin rpy="0 0 0" xyz="0 0 0"/>
    <parent link="floating_base"/>
    <child link="torso"/>
  </joint>

  <link name="torso">
    <visual>
      <origin rpy="0 0 0" xyz="0 0 0"/>
      <geometry>
        <box size="0.432 0.146 0.17"/>
        <!-- <mesh filename="/home/haoyun/Data/Code/drake/workspace/centaur_sim/centaur_description/meshes/obj/shank.obj" scale="1 1 1"/> -->
      </geometry>
      <material name="grey"/>
    </visual>
    <collision>
      <origin rpy="0 0 0" xyz="0 0 0"/>
      <geometry>
        <box size="0.432 0.146 0.17"/>
      </geometry>
    </collision>
    <inertial>
      <origin rpy="0 0 0" xyz="0.0 0.0 0.0"/>
      <mass value="20.0"/>
      <inertia ixx="0.0837" ixy="0" ixz="0" iyy="0.3592" iyz="0" izz="0.3466"/>
    </inertial>
  </link>  

  <joint name="hind_left_hip_joint" type="revolute">
    <origin rpy="0 0 0" xyz="-0.048 0.173 0"/>
    <parent link="torso"/>
    <child link="hind_left_hip"/>
    <axis xyz="1 0 0"/>
    <dynamics damping="0" friction="0"/>
    <limit effort="140" lower="-0.8028514559173915" upper="0.8028514559173915" velocity="93"/>
  </joint>
  <transmission name="left_abad_trans" type="SimpleTransmission">
    <actuator name="tau_0"/>
    <joint name="hind_left_hip_joint"/>
    <mechanicalReduction>1</mechanicalReduction>
  </transmission>

  <link name="hind_left_hip">
    <visual>
      <origin rpy="1.5707963267948966 0 0" xyz="-0.084 0 0"/>
      <geometry>
        <cylinder length="0.127" radius="0.084"/>
      </geometry>
    </visual>
    <collision>
      <origin rpy="1.5707963267948966 0 0" xyz="-0.084 0 0"/>
      <geometry>
        <cylinder length="0.127" radius="0.084"/>
      </geometry>
    </collision>
    <inertial>
      <origin rpy="1.5707963267948966 0 0" xyz="-0.084 0 0"/>
      <mass value="1.7"/>
      <inertia ixx="0.0053" iyy="0.0053" izz="0.006"/>
    </inertial>
  </link>

  <joint name="hind_left_thigh_joint" type="revolute">
    <origin rpy="0 0 0" xyz="-0.084 0 0"/>
    <parent link="hind_left_hip"/>
    <child link="hind_left_thigh"/>
    <axis xyz="0 1 0"/>
    <dynamics damping="0" friction="0"/>
    <limit effort="140" lower="-0.3" upper="1.2" velocity="93"/>
  </joint>
  <transmission name="left_hip_trans" type="SimpleTransmission">
    <actuator name="tau_1"/>
    <joint name="hind_left_thigh_joint"/>
    <mechanicalReduction>1</mechanicalReduction>
  </transmission>

  <link name="hind_left_thigh">
    <visual>
      <origin rpy="0 0 0" xyz="0 0 -0.29"/>
      <geometry>
        <cylinder length="0.58" radius="0.0175"/>
      </geometry>
      <material name="grey"/>
    </visual>
    <collision>
      <origin rpy="0 0 0" xyz="0 0 -0.29"/>
      <geometry>
        <cylinder length="0.58" radius="0.0175"/>
      </geometry>
    </collision>
    <inertial>
      <origin rpy="0 0 0" xyz="0 0 -0.29"/>
      <mass value="0.5"/>
      <inertia ixx="0.0141" iyy="0.0141" izz="0.0001"/>
    </inertial>
  </link>

  <joint name="hind_left_knee_joint" type="revolute">
    <origin rpy="0 0 0" xyz="0 0 -0.58"/>
    <parent link="hind_left_thigh"/>
    <child link="hind_left_shank"/>
    <axis xyz="0 1 0"/>
    <dynamics damping="0" friction="0"/>
    <limit effort="140" lower="-1.2" upper="0" velocity="93"/>
  </joint>
  <transmission name="left_knee_trans" type="SimpleTransmission">
    <actuator name="tau_2"/>
    <joint name="hind_left_knee_joint"/>
    <mechanicalReduction>1</mechanicalReduction>
  </transmission>

  <link name="hind_left_shank">
    <visual>
      <origin rpy="0 0 0" xyz="0 0 -0.2225"/>
      <geometry>
        <cylinder length="0.445" radius="0.015"/>
      </geometry>
      <material name="grey"/>
    </visual>
    <collision>
      <origin rpy="0 0 0" xyz="0 0 -0.2225"/>
      <geometry>
        <cylinder length="0.445" radius="0.015"/>
      </geometry>
    </collision>
    <inertial>
      <origin rpy="0 0 0" xyz="0 0 -0.2225"/>
      <mass value="0.5"/>
      <inertia ixx="0.0083" iyy="0.0083" izz="0.0001"/>
    </inertial>
  </link>

  <joint name="left_foot_fixed_joint" type="fixed">
    <origin rpy="0 0 0" xyz="0 0 -0.455"/>
    <parent link="hind_left_shank"/>
    <child link="hind_left_foot"/>
  </joint>

  <link name="hind_left_foot">
    <visual>
      <origin rpy="0 0 0" xyz="0 0 0"/>
      <geometry>
        <sphere radius="0.02"/>
      </geometry>
      <material name="orange"/>
    </visual>
    <collision>
      <origin rpy="0 0 0" xyz="0 0 -0.02"/>
      <geometry>
        <sphere radius="0.02"/>
      </geometry>
    </collision>
  </link>
  
  <!-- right side -->

  <joint name="hind_right_hip_joint" type="revolute">
    <origin rpy="0 0 0" xyz="-0.048 -0.173 0"/>
    <parent link="torso"/>
    <child link="hind_right_hip"/>
    <axis xyz="1 0 0"/>
    <dynamics damping="0" friction="0"/>
    <limit effort="140" lower="-0.8028514559173915" upper="0.8028514559173915" velocity="93"/>
  </joint>
  <transmission name="right_abad_trans" type="SimpleTransmission">
    <actuator name="tau_3"/>
    <joint name="hind_right_hip_joint"/>
    <mechanicalReduction>1</mechanicalReduction>
  </transmission>

  <link name="hind_right_hip">
    <visual>
      <origin rpy="1.5707963267948966 0 0" xyz="-0.084 0 0"/>
      <geometry>
        <cylinder length="0.127" radius="0.084"/>
      </geometry>
    </visual>
    <collision>
      <origin rpy="1.5707963267948966 0 0" xyz="-0.084 0 0"/>
      <geometry>
        <cylinder length="0.127" radius="0.084"/>
      </geometry>
    </collision>
    <inertial>
      <origin rpy="1.5707963267948966 0 0" xyz="-0.084 0 0"/>
      <mass value="1.7"/>
      <inertia ixx="0.0053" iyy="0.0053" izz="0.006"/>
    </inertial>
  </link>

  <joint name="hind_right_thigh_joint" type="revolute">
    <origin rpy="0 0 0" xyz="-0.084 0 0"/>
    <parent link="hind_right_hip"/>
    <child link="hind_right_thigh"/>
    <axis xyz="0 1 0"/>
    <dynamics damping="0" friction="0"/>
    <limit effort="140" lower="-0.3" upper="1.2" velocity="93"/>
  </joint>
  <transmission name="right_hip_trans" type="SimpleTransmission">
    <actuator name="tau_4"/>
    <joint name="hind_right_thigh_joint"/>
    <mechanicalReduction>1</mechanicalReduction>
  </transmission>

  <link name="hind_right_thigh">
    <visual>
      <origin rpy="0 0 0" xyz="0 0 -0.29"/>
      <geometry>
        <cylinder length="0.58" radius="0.0175"/>
      </geometry>
      <material name="grey"/>
    </visual>
    <collision>
      <origin rpy="0 0 0" xyz="0 0 -0.29"/>
      <geometry>
        <cylinder length="0.58" radius="0.0175"/>
      </geometry>
    </collision>
    <inertial>
      <origin rpy="0 0 0" xyz="0 0 -0.29"/>
      <mass value="0.5"/>
      <inertia ixx="0.0141" iyy="0.0141" izz="0.0001"/>
    </inertial>
  </link>

  <joint name="hind_right_knee_joint" type="revolute">
    <origin rpy="0 0 0" xyz="0 0 -0.58"/>
    <parent link="hind_right_thigh"/>
    <child link="hind_right_shank"/>
    <axis xyz="0 1 0"/>
    <dynamics damping="0" friction="0"/>
    <limit effort="140" lower="-1.2" upper="0" velocity="93"/>
  </joint>
  <transmission name="right_knee_trans" type="SimpleTransmission">
    <actuator name="tau_5"/>
    <joint name="hind_right_knee_joint"/>
    <mechanicalReduction>1</mechanicalReduction>
  </transmission>

  <link name="hind_right_shank">
    <visual>
      <origin rpy="0 0 0" xyz="0 0 -0.2225"/>
      <geometry>
        <cylinder length="0.445" radius="0.015"/>
      </geometry>
      <material name="grey"/>
    </visual>
    <collision>
      <origin rpy="0 0 0" xyz="0 0 -0.2225"/>
      <geometry>
        <cylinder length="0.445" radius="0.015"/>
      </geometry>
    </collision>
    <inertial>
      <origin rpy="0 0 0" xyz="0 0 -0.2225"/>
      <mass value="0.5"/>
      <inertia ixx="0.0083" iyy="0.0083" izz="0.0001"/>
    </inertial>
  </link>

  <joint name="right_foot_fixed_joint" type="fixed">
    <origin rpy="0 0 0" xyz="0 0 -0.455"/>
    <parent link="hind_right_shank"/>
    <child link="hind_right_foot"/>
  </joint>

  <link name="hind_right_foot">
    <visual>
      <origin rpy="0 0 0" xyz="0 0 0"/>
      <geometry>
        <sphere radius="0.02"/>
      </geometry>
      <material name="orange"/>
    </visual>
    <collision>
      <origin rpy="0 0 0" xyz="0 0 -0.02"/>
      <geometry>
        <sphere radius="0.02"/>
      </geometry>
    </collision>
  </link>
  








  





</robot>