<?xml version='1.0'?>
<sdf version='1.9'>
  <model name='centaur_control_model'>

  <link name='floating_base'>
    <pose>-0.216 0 0.905 0 0 0</pose>
    <visual name='visual'>
      <pose>-0.216 0 0.905 0 0 0</pose>
      <geometry> <sphere> <radius>0.02</radius> </sphere> </geometry>
      <material>
        <diffuse>0.8 0.1 0.1 0.1</diffuse>
      </material>
    </visual>  
  </link>

  <joint name='floating_base_fixed_to_torso' type='fixed'>
    <parent>floating_base</parent>
    <child>torso</child>
  </joint>

  <link name='torso'>
    <pose relative_to='floating_base'>0 0 0 0 0 0</pose>
    <visual name='visual'>
      <pose relative_to='floating_base'>0 0 0 0 0 0</pose>
      <geometry> 
        <box> <size>0.432 0.146 0.17</size> </box>
      </geometry>
      <material>
        <diffuse>0.2 0.2 0.2 0.4</diffuse>
      </material>
    </visual>
  </link>

  <frame name='left_abad_joint_frame' attached_to='torso'>
    <pose relative_to='torso'>-0.048 0.173 0 0 0 0</pose>
  </frame>

  <joint name='left_abad_joint' type='revolute'>
    <pose relative_to='left_abad_joint_frame'>0 0 0 0 0 0</pose>
    <parent>torso</parent>
    <child>left_hip_from_abad</child>
    <axis>  
      <xyz>1 0 0</xyz>
      <limit> 
        <lower>-0.8028514559173915</lower>
        <upper>0.8028514559173915</upper>
        <effort>140.0</effort>
        <velocity>93.0</velocity>
      </limit>
    </axis>
  </joint>

  <link name='left_hip_from_abad'>
    <pose relative_to='left_abad_joint_frame'>0 0 0 0 0 0</pose>
    <visual name='visual'>
      <pose relative_to='left_abad_joint_frame'>-0.084 0 0 1.5707963267948966 0 0</pose>
      <geometry>
        <!-- <mesh> <uri>/home/haoyun/Data/Code/drake/workspace/centuar_sim/centuar_description/meshes/dae/hip.dae</uri> </mesh> -->
        <cylinder> <length>0.127</length> <radius>0.084</radius> </cylinder>
      </geometry>
      <material>
        <diffuse>0.913725490196 0.913725490196 0.847058823529 0.6</diffuse>
      </material>
    </visual>
    <collision name='collision'>
      <pose relative_to='left_abad_joint_frame'>-0.084 0 0 1.5707963267948966 0 0</pose>
      <geometry>
        <cylinder> <length>0.127</length> <radius>0.084</radius> </cylinder>
      </geometry>
    </collision>
    <inertial>
      <pose>-0.084 0 0 1.5707963267948966 0 0</pose>
      <mass>1.7</mass>
      <inertia> <ixx>0.0053</ixx> <iyy>0.0053</iyy> <izz>0.006</izz> </inertia>
    </inertial>
  </link>

  <frame name='left_hip_joint_frame' attached_to='left_hip_from_abad'>
    <pose relative_to='left_hip_from_abad'>-0.084 0 0 0 0 0</pose>
  </frame>

  <joint name='left_hip_joint' type='revolute'>
    <pose relative_to='left_hip_joint_frame'>0 0 0 0 0 0</pose>
    <parent>left_hip_from_abad</parent>
    <child>left_thigh_from_hip</child>
    <axis>  
      <xyz>0 1 0</xyz>
      <limit> 
        <lower>-0.8028514559173915</lower>
        <upper>0.8028514559173915</upper>
        <effort>140.0</effort>
        <velocity>93.0</velocity>
      </limit>
    </axis>
  </joint>

  <link name='left_thigh_from_hip'>
    <pose relative_to='left_hip_joint_frame'>0 0 0 0 0 0</pose>
    <visual name='visual'>
      <pose relative_to='left_hip_joint_frame'>0 0 -0.29 0 0 0</pose>
      <geometry>
        <cylinder> <length>0.58</length> <radius>0.0175</radius> </cylinder>
      </geometry>
      <material>
        <diffuse>0.913725490196 0.913725490196 0.847058823529 0.6</diffuse>
      </material>
    </visual>
    <collision name='collision'>
      <pose relative_to='left_hip_joint_frame'>0 0 -0.29 0 0 0</pose>
      <geometry>
        <cylinder> <length>0.58</length> <radius>0.0175</radius> </cylinder>
      </geometry>
    </collision>
    <inertial>
      <pose>0 0 -0.29 0 0 0</pose>
      <mass>0.5</mass>
      <inertia> <ixx>0.0141</ixx> <iyy>0.0141</iyy> <izz>0.0001</izz> </inertia>
    </inertial>
  </link>

  <frame name='left_knee_joint_frame' attached_to='left_thigh_from_hip'>
    <pose relative_to='left_thigh_from_hip'>0 0 -0.58 0 0 0</pose>
  </frame>

  <joint name='left_knee_joint' type='revolute'>
    <pose relative_to='left_knee_joint_frame'>0 0 0 0 0 0</pose>
    <parent>left_thigh_from_hip</parent>
    <child>left_shank_from_knee</child>
    <axis>  
      <xyz>0 1 0</xyz>
      <limit> 
        <lower>-1.5</lower>
        <upper>0.0</upper>
        <effort>140.0</effort>
        <velocity>93.0</velocity>
      </limit>
    </axis>
  </joint>

  <link name='left_shank_from_knee'>
    <pose relative_to='left_knee_joint_frame'>0 0 0 0 0 0</pose>
    <visual name='visual'>
      <pose relative_to='left_knee_joint_frame'>0 0 -0.2225 0 0 0</pose>
      <geometry>
        <cylinder> <length>0.445</length> <radius>0.015</radius> </cylinder>
      </geometry>
      <material>
        <diffuse>0.913725490196 0.913725490196 0.847058823529 0.6</diffuse>
      </material>
    </visual>
    <collision name='collision'>
      <pose relative_to='left_knee_joint_frame'>0 0 -0.2225 0 0 0</pose>
      <geometry>
        <cylinder> <length>0.445</length> <radius>0.015</radius> </cylinder>
      </geometry>
    </collision>
    <inertial>
      <pose>0 0 -0.2225 0 0 0</pose>
      <mass>0.5</mass>
      <inertia> <ixx>0.0083</ixx> <iyy>0.0083</iyy> <izz>0.0001</izz> </inertia>
    </inertial>
  </link>

  <frame name='left_foot_joint_frame' attached_to='left_shank_from_knee'>
    <pose relative_to='left_shank_from_knee'>0 0 -0.455 0 0 0</pose>
  </frame>

  <joint name='left_foot_fixed_joint' type='fixed'>
    <pose relative_to='left_foot_joint_frame'>0 0 0 0 0 0</pose>
    <parent>left_shank_from_knee</parent>
    <child>left_foot</child>
  </joint>

  <link name='left_foot'>
    <pose relative_to='left_foot_joint_frame'>0 0 0 0 0 0</pose>
    <visual name='visual'>
      <pose relative_to='left_foot_joint_frame'>0 0 0 0 0 0</pose>
      <geometry>
        <sphere> <radius>0.02</radius> </sphere>
      </geometry>
      <material>
        <diffuse>1.0 0.423529411765 0.0392156862745 0.5</diffuse>
      </material>
    </visual>
    <collision name='collision'>
      <pose relative_to='left_foot_joint_frame'>0 0 0 0 0 0</pose>
      <geometry>
        <sphere> <radius>0.02</radius> </sphere>
      </geometry>
    </collision>
  </link>


<!-- right side -->

  <frame name='right_abad_joint_frame' attached_to='torso'>
    <pose relative_to='torso'>-0.048 -0.173 0 0 0 0</pose>
  </frame>

  <joint name='right_abad_joint' type='revolute'>
    <pose relative_to='right_abad_joint_frame'>0 0 0 0 0 0</pose>
    <parent>torso</parent>
    <child>right_hip_from_abad</child>
    <axis>  
      <xyz>1 0 0</xyz>
      <limit> 
        <lower>-0.8028514559173915</lower>
        <upper>0.8028514559173915</upper>
        <effort>140.0</effort>
        <velocity>93.0</velocity>
      </limit>
    </axis>
  </joint>

  <link name='right_hip_from_abad'>
    <pose relative_to='right_abad_joint_frame'>0 0 0 0 0 0</pose>
    <visual name='visual'>
      <pose relative_to='right_abad_joint_frame'>-0.084 0 0 1.5707963267948966 0 0</pose>
      <geometry>
        <!-- <mesh> <uri>/home/haoyun/Data/Code/drake/workspace/centuar_sim/centuar_description/meshes/dae/hip.dae</uri> </mesh> -->
        <cylinder> <length>0.127</length> <radius>0.084</radius> </cylinder>
      </geometry>
      <material>
        <diffuse>0.913725490196 0.913725490196 0.847058823529 0.6</diffuse>
      </material>
    </visual>
    <collision name='collision'>
      <pose relative_to='right_abad_joint_frame'>-0.084 0 0 1.5707963267948966 0 0</pose>
      <geometry>
        <cylinder> <length>0.127</length> <radius>0.084</radius> </cylinder>
      </geometry>
    </collision>
    <inertial>
      <pose>-0.084 0 0 1.5707963267948966 0 0</pose>
      <mass>1.7</mass>
      <inertia> <ixx>0.0053</ixx> <iyy>0.0053</iyy> <izz>0.006</izz> </inertia>
    </inertial>
  </link>

  <frame name='right_hip_joint_frame' attached_to='right_hip_from_abad'>
    <pose relative_to='right_hip_from_abad'>-0.084 0 0 0 0 0</pose>
  </frame>

  <joint name='right_hip_joint' type='revolute'>
    <pose relative_to='right_hip_joint_frame'>0 0 0 0 0 0</pose>
    <parent>right_hip_from_abad</parent>
    <child>right_thigh_from_hip</child>
    <axis>  
      <xyz>0 1 0</xyz>
      <limit> 
        <lower>-0.8028514559173915</lower>
        <upper>0.8028514559173915</upper>
        <effort>140.0</effort>
        <velocity>93.0</velocity>
      </limit>
    </axis>
  </joint>

  <link name='right_thigh_from_hip'>
    <pose relative_to='right_hip_joint_frame'>0 0 0 0 0 0</pose>
    <visual name='visual'>
      <pose relative_to='right_hip_joint_frame'>0 0 -0.29 0 0 0</pose>
      <geometry>
        <cylinder> <length>0.58</length> <radius>0.0175</radius> </cylinder>
      </geometry>
      <material>
        <diffuse>0.913725490196 0.913725490196 0.847058823529 0.6</diffuse>
      </material>
    </visual>
    <collision name='collision'>
      <pose relative_to='right_hip_joint_frame'>0 0 -0.29 0 0 0</pose>
      <geometry>
        <cylinder> <length>0.58</length> <radius>0.0175</radius> </cylinder>
      </geometry>
    </collision>
    <inertial>
      <pose>0 0 -0.29 0 0 0</pose>
      <mass>0.5</mass>
      <inertia> <ixx>0.0141</ixx> <iyy>0.0141</iyy> <izz>0.0001</izz> </inertia>
    </inertial>
  </link>

  <frame name='right_knee_joint_frame' attached_to='right_thigh_from_hip'>
    <pose relative_to='right_thigh_from_hip'>0 0 -0.58 0 0 0</pose>
  </frame>

  <joint name='right_knee_joint' type='revolute'>
    <pose relative_to='right_knee_joint_frame'>0 0 0 0 0 0</pose>
    <parent>right_thigh_from_hip</parent>
    <child>right_shank_from_knee</child>
    <axis>  
      <xyz>0 1 0</xyz>
      <limit> 
        <lower>-1.5</lower>
        <upper>0.0</upper>
        <effort>140.0</effort>
        <velocity>93.0</velocity>
      </limit>
    </axis>
  </joint>

  <link name='right_shank_from_knee'>
    <pose relative_to='right_knee_joint_frame'>0 0 0 0 0 0</pose>
    <visual name='visual'>
      <pose relative_to='right_knee_joint_frame'>0 0 -0.2225 0 0 0</pose>
      <geometry>
        <cylinder> <length>0.445</length> <radius>0.015</radius> </cylinder>
      </geometry>
      <material>
        <diffuse>0.913725490196 0.913725490196 0.847058823529 0.6</diffuse>
      </material>
    </visual>
    <collision name='collision'>
      <pose relative_to='right_knee_joint_frame'>0 0 -0.2225 0 0 0</pose>
      <geometry>
        <cylinder> <length>0.445</length> <radius>0.015</radius> </cylinder>
      </geometry>
    </collision>
    <inertial>
      <pose>0 0 -0.2225 0 0 0</pose>
      <mass>0.5</mass>
      <inertia> <ixx>0.0083</ixx> <iyy>0.0083</iyy> <izz>0.0001</izz> </inertia>
    </inertial>
  </link>

  <frame name='right_foot_joint_frame' attached_to='right_shank_from_knee'>
    <pose relative_to='right_shank_from_knee'>0 0 -0.455 0 0 0</pose>
  </frame>

  <joint name='right_foot_fixed_joint' type='fixed'>
    <pose relative_to='right_foot_joint_frame'>0 0 0 0 0 0</pose>
    <parent>right_shank_from_knee</parent>
    <child>right_foot</child>
  </joint>

  <link name='right_foot'>
    <pose relative_to='right_foot_joint_frame'>0 0 0 0 0 0</pose>
    <visual name='visual'>
      <pose relative_to='right_foot_joint_frame'>0 0 0 0 0 0</pose>
      <geometry>
        <sphere> <radius>0.02</radius> </sphere>
      </geometry>
      <material>
        <diffuse>1.0 0.423529411765 0.0392156862745 0.5</diffuse>
      </material>
    </visual>
    <collision name='collision'>
      <pose relative_to='right_foot_joint_frame'>0 0 0 0 0 0</pose>
      <geometry>
        <sphere> <radius>0.02</radius> </sphere>
      </geometry>
    </collision>
  </link>



  </model>


</sdf>