<?xml version='1.0'?>
<sdf version='1.9'>
  <model name='centaur_sim_scene'>

  <link name='ground'>
    <visual name='visual'>
      <pose>0 0 -0.025 0 0 0</pose>
      <geometry>
        <box>  <size>10.0 8.0 0.05</size> </box>
      </geometry>
      <material>
        <diffuse>0.9 0.8 0.7 0.6</diffuse>
      </material>
    </visual> 
    <collision name="collision">
      <pose>0 0 -0.025 0 0 0</pose>
      <geometry>
        <box>  <size>10.0 8.0 0.05</size> </box>
      </geometry>
    </collision>
  </link>

  <frame name='ball_joint_frame' attached_to='ground'> 
    <pose relative_to='ground'>0.216 0 0.91 0 0 0</pose>
  </frame>

  <joint name='ball_joint' type='ball'>
    <pose relative_to='ball_joint_frame'>0 0 0 0 0 0</pose>
    <parent>ground</parent>
    <child>floating_base</child>
  </joint>

  <link name='floating_base'>
    <pose relative_to='ball_joint_frame'>-0.216 0 0 0 0 0</pose>
    <visual name='visual'>
      <pose relative_to='ball_joint_frame'>-0.216 0 0 0 0 0</pose>
      <geometry> <sphere> <radius>0.02</radius> </sphere> </geometry>
      <material>
        <diffuse>0.8 0.1 0.1 0.6</diffuse>
      </material>
    </visual>  
  </link>

  <joint name='floating_base_fixed_to_torso' type='fixed'>
    <parent>floating_base</parent>
    <child>torso</child>
  </joint>

  <link name='torso'>
    <visual name='visual'>
      <pose relative_to='floating_base'>0 0 0 0 0 0</pose>
      <geometry> 
        <box> <size>0.432 0.146 0.17</size> </box>
      </geometry>
      <material>
        <diffuse>0.2 0.2 0.2 0.4</diffuse>
      </material>
    </visual>
  </link>

  </model>


</sdf>